Workbook

Sheet Dashboard
A1: 💶 GESTIONE FINANZE FAMILIARI | I1: ="Dati al "&TEXT(MAX(Transazioni!$A$2:$A$494),"dd/mm/yyyy") -> Dati al 27/08/2026
A3: ="Buonasera, "&Budget!$B$15 -> Buonasera, Andrea | G3: Mese: | H3: Ago 2026
A4: Ecco il riepilogo delle finanze familiari | G4: ="Transazioni nel mese: "&Supporto!$J$10 -> Transazioni nel mese: 31
A7: SALDO TOTALE | C7: ENTRATE MESE | E7: USCITE MESE | G7: RISPARMIO MESE | I7: TASSO DI RISPARMIO | K7: TOP SPESA DEL MESE
A8: =Supporto!$J$11 -> 33947.02 | C8: =Supporto!$J$5 -> 4401.16 | E8: =Supporto!$J$6 -> 2208.82 | G8: =Supporto!$J$7 -> 2192.34 | I8: =Supporto!$J$8 -> 0.49812777 | K8: =Supporto!$J$32 -> Casa e Bollette
A9: ="Patrimonio netto attuale" -> Patrimonio netto attuale | C9: ="Mese selezionato: "&$H$3 -> Mese selezionato: Ago 2026 | E9: ="N. transazioni: "&Supporto!$J$10 -> N. transazioni: 31 | G9: =IF(Supporto!$J$9="","Primo mese disponibile","vs mese prec.: "&TEXT(Supporto!$J$9,"€#,##0;-€#,##0")) -> vs mese prec.: -€248 | I9: ="Obiettivo: "&TEXT(Budget!$B$16,"0%") -> Obiettivo: 20% | K9: ="€"&TEXT(Supporto!$J$33,"#,##0")&" questo mese" -> €880 questo mese
A11: ="Andamento Patrimonio ("&Supporto!$J$12&" mesi)" -> Andamento Patrimonio (14 mesi) | H11: ="Ripartizione Spese — "&$H$3 -> Ripartizione Spese — Ago 2026
A26: Analisi Spese per Categoria (Mese Selezionato) | H26: Transazioni Recenti (Mese Selezionato)
A27: Categoria | C27: Speso / Budget | E27: % Utilizzo | H27: Data | I27: Categoria | L27: Tipo | M27: Valore
A28: =Supporto!A21 -> Alimentari | C28: ="€"&TEXT(Supporto!B21,"#,##0")&" / €"&TEXT(Supporto!C21,"#,##0") -> €583 / €550 | E28: =Supporto!D21 -> 1.0596909 | H28: =Supporto!B40 -> 46261.534 | I28: =Supporto!C40 -> Salute | L28: =IF(Supporto!D40="Entrata","▲","▼") -> ▼ | M28: =Supporto!F40 -> -53.54
A29: =Supporto!A22 -> Casa e Bollette | C29: ="€"&TEXT(Supporto!B22,"#,##0")&" / €"&TEXT(Supporto!C22,"#,##0") -> €880 / €900 | E29: =Supporto!D22 -> 0.97767778 | H29: =Supporto!B41 -> 46261.44 | I29: =Supporto!C41 -> Istruzione | L29: =IF(Supporto!D41="Entrata","▲","▼") -> ▼ | M29: =Supporto!F41 -> -83.75
A30: =Supporto!A23 -> Trasporti | C30: ="€"&TEXT(Supporto!B23,"#,##0")&" / €"&TEXT(Supporto!C23,"#,##0") -> €141 / €140 | E30: =Supporto!D23 -> 1.0039286 | H30: =Supporto!B42 -> 46261.378 | I30: =Supporto!C42 -> Stipendio Partner | L30: =IF(Supporto!D42="Entrata","▲","▼") -> ▲ | M30: =Supporto!F42 -> 1999.98
A31: =Supporto!A24 -> Ristoranti e Bar | C31: ="€"&TEXT(Supporto!B24,"#,##0")&" / €"&TEXT(Supporto!C24,"#,##0") -> €130 / €160 | E31: =Supporto!D24 -> 0.8150625 | H31: =Supporto!B43 -> 46261.375 | I31: =Supporto!C43 -> Stipendio | L31: =IF(Supporto!D43="Entrata","▲","▼") -> ▲ | M31: =Supporto!F43 -> 2352.62
A32: =Supporto!A25 -> Svago | C32: ="€"&TEXT(Supporto!B25,"#,##0")&" / €"&TEXT(Supporto!C25,"#,##0") -> €78 / €100 | E32: =Supporto!D25 -> 0.7779 | H32: =Supporto!B44 -> 46260.917 | I32: =Supporto!C44 -> Ristoranti e Bar | L32: =IF(Supporto!D44="Entrata","▲","▼") -> ▼ | M32: =Supporto!F44 -> -57.89
A33: =Supporto!A26 -> Salute | C33: ="€"&TEXT(Supporto!B26,"#,##0")&" / €"&TEXT(Supporto!C26,"#,##0") -> €137 / €90 | E33: =Supporto!D26 -> 1.5187778 | H33: =Supporto!B45 -> 46260.738 | I33: =Supporto!C45 -> Trasporti | L33: =IF(Supporto!D45="Entrata","▲","▼") -> ▼ | M33: =Supporto!F45 -> -31.63
A34: =Supporto!A27 -> Istruzione | C34: ="€"&TEXT(Supporto!B27,"#,##0")&" / €"&TEXT(Supporto!C27,"#,##0") -> €84 / €60 | E34: =Supporto!D27 -> 1.3958333 | H34: =Supporto!B46 -> 46257.925 | I34: =Supporto!C46 -> Trasporti | L34: =IF(Supporto!D46="Entrata","▲","▼") -> ▼ | M34: =Supporto!F46 -> -30.16
A35: =Supporto!A28 -> Abbigliamento | C35: ="€"&TEXT(Supporto!B28,"#,##0")&" / €"&TEXT(Supporto!C28,"#,##0") -> €41 / €90 | E35: =Supporto!D28 -> 0.46022222 | H35: =Supporto!B47 -> 46257.878 | I35: =Supporto!C47 -> Trasporti | L35: =IF(Supporto!D47="Entrata","▲","▼") -> ▼ | M35: =Supporto!F47 -> -9.97
A36: =Supporto!A29 -> Assicurazioni | C36: ="€"&TEXT(Supporto!B29,"#,##0")&" / €"&TEXT(Supporto!C29,"#,##0") -> €98 / €100 | E36: =Supporto!D29 -> 0.9837 | H36: =Supporto!B48 -> 46255.694 | I36: =Supporto!C48 -> Altre Spese | L36: =IF(Supporto!D48="Entrata","▲","▼") -> ▼ | M36: =Supporto!F48 -> -13.54
A37: =Supporto!A30 -> Altre Spese | C37: ="€"&TEXT(Supporto!B30,"#,##0")&" / €"&TEXT(Supporto!C30,"#,##0") -> €37 / €90 | E37: =Supporto!D30 -> 0.41222222 | H37: =Supporto!B49 -> 46253.381 | I37: =Supporto!C49 -> Svago | L37: =IF(Supporto!D49="Entrata","▲","▼") -> ▼ | M37: =Supporto!F49 -> -3
A39: =IF(Supporto!$J$35>1,"⚠ Attenzione: hai superato il budget di "&Supporto!$J$34&" di €"&TEXT(Supporto!$J$37,"#,##0")&" — "&Supporto!$J$36&" categorie fuori budget questo mese.","✓ Tutte le categorie di spesa sono in linea con il budget questo mese.") -> ⚠ Attenzione: hai superato il budget di Salute di €47 — 4 categorie fuori budget questo mese.
A43: ="Fonte dati: foglio Transazioni ("&COUNTA(Transazioni!$A$2:$A$494)&" transazioni caricate da CSV)" -> Fonte dati: foglio Transazioni (493 transazioni caricate da CSV) | H43: Modifica il budget nel foglio Budget · seleziona il mese in alto per aggiornare la dashboard

Sheet Transazioni
A1: Data e Ora | B1: Categoria | C1: Tipo | D1: Valore | E1: Anno | F1: Mese | G1: AnnoMese | H1: MeseEtichetta | I1: Rank | J1: RankMese
A2: 45841.582 | B2: Ristoranti e Bar | C2: Uscita | D2: 13.58 | E2: =YEAR(A2) -> 2025 | F2: =MONTH(A2) -> 7 | G2: =E2*100+F2 -> 202507 | H2: =CHOOSE(F2,"Gen","Feb","Mar","Apr","Mag","Giu","Lug","Ago","Set","Ott","Nov","Dic")&" "&E2 -> Lug 2025 | I2: =SUMPRODUCT(($A$2:$A$494>A2)*1)+1 -> 493 | J2: =IF(G2=Supporto!$J$4,SUMPRODUCT(($G$2:$G$494=Supporto!$J$4)*($A$2:$A$494>A2))+1,"")
A3: 45842.795 | B3: Casa e Bollette | C3: Uscita | D3: 39.95 | E3: =YEAR(A3) -> 2025 | F3: =MONTH(A3) -> 7 | G3: =E3*100+F3 -> 202507 | H3: =CHOOSE(F3,"Gen","Feb","Mar","Apr","Mag","Giu","Lug","Ago","Set","Ott","Nov","Dic")&" "&E3 -> Lug 2025 | I3: =SUMPRODUCT(($A$2:$A$494>A3)*1)+1 -> 492 | J3: =IF(G3=Supporto!$J$4,SUMPRODUCT(($G$2:$G$494=Supporto!$J$4)*($A$2:$A$494>A3))+1,"")
A4: 45843.575 | B4: Alimentari | C4: Uscita | D4: 46.16 | E4: =YEAR(A4) -> 2025 | F4: =MONTH(A4) -> 7 | G4: =E4*100+F4 -> 202507 | H4: =CHOOSE(F4,"Gen","Feb","Mar","Apr","Mag","Giu","Lug","Ago","Set","Ott","Nov","Dic")&" "&E4 -> Lug 2025 | I4: =SUMPRODUCT(($A$2:$A$494>A4)*1)+1 -> 491 | J4: =IF(G4=Supporto!$J$4,SUMPRODUCT(($G$2:$G$494=Supporto!$J$4)*($A$2:$A$494>A4))+1,"")
A5: 45843.92 | B5: Salute | C5: Uscita | D5: 19.74 | E5: =YEAR(A5) -> 2025 | F5: =MONTH(A5) -> 7 | G5: =E5*100+F5 -> 202507 | H5: =CHOOSE(F5,"Gen","Feb","Mar","Apr","Mag","Giu","Lug","Ago","Set","Ott","Nov","Dic")&" "&E5 -> Lug 2025 | I5: =SUMPRODUCT(($A$2:$A$494>A5)*1)+1 -> 490 | J5: =IF(G5=Supporto!$J$4,SUMPRODUCT(($G$2:$G$494=Supporto!$J$4)*($A$2:$A$494>A5))+1,"")
A6: 45845.376 | B6: Casa e Bollette | C6: Uscita | D6: 497.06 | E6: =YEAR(A6) -> 2025 | F6: =MONTH(A6) -> 7 | G6: =E6*100+F6 -> 202507 | H6: =CHOOSE(F6,"Gen","Feb","Mar","Apr","Mag","Giu","Lug","Ago","Set","Ott","Nov","Dic")&" "&E6 -> Lug 2025 | I6: =SUMPRODUCT(($A$2:$A$494>A6)*1)+1 -> 489 | J6: =IF(G6=Supporto!$J$4,SUMPRODUCT(($G$2:$G$494=Supporto!$J$4)*($A$2:$A$494>A6))+1,"")
A7: 45846.745 | B7: Ristoranti e Bar | C7: Uscita | D7: 49.15 | E7: =YEAR(A7) -> 2025 | F7: =MONTH(A7) -> 7 | G7: =E7*100+F7 -> 202507 | H7: =CHOOSE(F7,"Gen","Feb","Mar","Apr","Mag","Giu","Lug","Ago","Set","Ott","Nov","Dic")&" "&E7 -> Lug 2025 | I7: =SUMPRODUCT(($A$2:$A$494>A7)*1)+1 -> 488 | J7: =IF(G7=Supporto!$J$4,SUMPRODUCT(($G$2:$G$494=Supporto!$J$4)*($A$2:$A$494>A7))+1,"")
A8: 45846.771 | B8: Rimborsi | C8: Entrata | D8: 48.14 | E8: =YEAR(A8) -> 2025 | F8: =MONTH(A8) -> 7 | G8: =E8*100+F8 -> 202507 | H8: =CHOOSE(F8,"Gen","Feb","Mar","Apr","Mag","Giu","Lug","Ago","Set","Ott","Nov","Dic")&" "&E8 -> Lug 2025 | I8: =SUMPRODUCT(($A$2:$A$494>A8)*1)+1 -> 487 | J8: =IF(G8=Supporto!$J$4,SUMPRODUCT(($G$2:$G$494=Supporto!$J$4)*($A$2:$A$494>A8))+1,"")
A9: 45847.469 | B9: Svago | C9: Uscita | D9: 38.49 | E9: =YEAR(A9) -> 2025 | F9: =MONTH(A9) -> 7 | G9: =E9*100+F9 -> 202507 | H9: =CHOOSE(F9,"Gen","Feb","Mar","Apr","Mag","Giu","Lug","Ago","Set","Ott","Nov","Dic")&" "&E9 -> Lug 2025 | I9: =SUMPRODUCT(($A$2:$A$494>A9)*1)+1 -> 486 | J9: =IF(G9=Supporto!$J$4,SUMPRODUCT(($G$2:$G$494=Supporto!$J$4)*($A$2:$A$494>A9))+1,"")
A10: 45849.42 | B10: Alimentari | C10: Uscita | D10: 6.83 | E10: =YEAR(A10) -> 2025 | F10: =MONTH(A10) -> 7 | G10: =E10*100+F10 -> 202507 | H10: =CHOOSE(F10,"Gen","Feb","Mar","Apr","Mag","Giu","Lug","Ago","Set","Ott","Nov","Dic")&" "&E10 -> Lug 2025 | I10: =SUMPRODUCT(($A$2:$A$494>A10)*1)+1 -> 485 | J10: =IF(G10=Supporto!$J$4,SUMPRODUCT(($G$2:$G$494=Supporto!$J$4)*($A$2:$A$494>A10))+1,"")
A11: 45849.803 | B11: Ristoranti e Bar | C11: Uscita | D11: 43.19 | E11: =YEAR(A11) -> 2025 | F11: =MONTH(A11) -> 7 | G11: =E11*100+F11 -> 202507 | H11: =CHOOSE(F11,"Gen","Feb","Mar","Apr","Mag","Giu","Lug","Ago","Set","Ott","Nov","Dic")&" "&E11 -> Lug 2025 | I11: =SUMPRODUCT(($A$2:$A$494>A11)*1)+1 -> 484 | J11: =IF(G11=Supporto!$J$4,SUMPRODUCT(($G$2:$G$494=Supporto!$J$4)*($A$2:$A$494>A11))+1,"")
A12: 45850.759 | B12: Trasporti | C12: Uscita | D12: 71.05 | E12: =YEAR(A12) -> 2025 | F12: =MONTH(A12) -> 7 | G12: =E12*100+F12 -> 202507 | H12: =CHOOSE(F12,"Gen","Feb","Mar","Apr","Mag","Giu","Lug","Ago","Set","Ott","Nov","Dic")&" "&E12 -> Lug 2025 | I12: =SUMPRODUCT(($A$2:$A$494>A12)*1)+1 -> 483 | J12: =IF(G12=Supporto!$J$4,SUMPRODUCT(($G$2:$G$494=Supporto!$J$4)*($A$2:$A$494>A12))+1,"")
A13: 45851.432 | B13: Alimentari | C13: Uscita | D13: 131.99 | E13: =YEAR(A13) -> 2025 | F13: =MONTH(A13) -> 7 | G13: =E13*100+F13 -> 202507 | H13: =CHOOSE(F13,"Gen","Feb","Mar","Apr","Mag","Giu","Lug","Ago","Set","Ott","Nov","Dic")&" "&E13 -> Lug 2025 | I13: =SUMPRODUCT(($A$2:$A$494>A13)*1)+1 -> 482 | J13: =IF(G13=Supporto!$J$4,SUMPRODUCT(($G$2:$G$494=Supporto!$J$4)*($A$2:$A$494>A13))+1,"")
... A494: 46261.534 | B494: Salute | C494: Uscita | D494: 53.54 | E494: =YEAR(A494) -> 2026 | F494: =MONTH(A494) -> 8 | G494: =E494*100+F494 -> 202608 | H494: =CHOOSE(F494,"Gen","Feb","Mar","Apr","Mag","Giu","Lug","Ago","Set","Ott","Nov","Dic")&" "&E494 -> Ago 2026 | I494: =SUMPRODUCT(($A$2:$A$494>A494)*1)+1 -> 1 | J494: =IF(G494=Supporto!$J$4,SUMPRODUCT(($G$2:$G$494=Supporto!$J$4)*($A$2:$A$494>A494))+1,"") -> 1

Sheet Budget
A1: Categoria | B1: Budget Mensile | C1: Note | D1: Tutte le Categorie
A2: Alimentari | B2: 550 | D2: Alimentari
A3: Casa e Bollette | B3: 900 | D3: Casa e Bollette
A4: Trasporti | B4: 140 | D4: Trasporti
A5: Ristoranti e Bar | B5: 160 | D5: Ristoranti e Bar
A6: Svago | B6: 100 | D6: Svago
A7: Salute | B7: 90 | D7: Salute
A8: Istruzione | B8: 60 | D8: Istruzione
A9: Abbigliamento | B9: 90 | D9: Abbigliamento
A10: Assicurazioni | B10: 100 | D10: Assicurazioni
A11: Altre Spese | B11: 90 | D11: Altre Spese
D12: Stipendio
D13: Stipendio Partner
A14: Impostazioni Personali | D14: Bonus
A15: Nome (per il saluto in Dashboard) | B15: Andrea | D15: Rimborsi
A16: Obiettivo Tasso di Risparmio | B16: 0.2 | D16: Altri Redditi

Sheet Supporto
A1: AnnoMese | B1: MeseEtichetta | C1: Entrate | D1: Uscite | E1: Risparmio | F1: TassoRisparmio | G1: SaldoCumulativo
A2: 202507 | B2: =CHOOSE(MOD(A2,100),"Gen","Feb","Mar","Apr","Mag","Giu","Lug","Ago","Set","Ott","Nov","Dic")&" "&INT(A2/100) -> Lug 2025 | C2: =SUMIFS(Transazioni!$D$2:$D$494,Transazioni!$G$2:$G$494,A2,Transazioni!$C$2:$C$494,"Entrata") -> 4601.92 | D2: =SUMIFS(Transazioni!$D$2:$D$494,Transazioni!$G$2:$G$494,A2,Transazioni!$C$2:$C$494,"Uscita") -> 2154.12 | E2: =C2-D2 -> 2447.8 | F2: =IFERROR(E2/C2,0) -> 0.53190842 | G2: =E2 -> 2447.8 | I2: MeseSelezionatoLabel | J2: =Dashboard!$H$3 -> Ago 2026
A3: 202508 | B3: =CHOOSE(MOD(A3,100),"Gen","Feb","Mar","Apr","Mag","Giu","Lug","Ago","Set","Ott","Nov","Dic")&" "&INT(A3/100) -> Ago 2025 | C3: =SUMIFS(Transazioni!$D$2:$D$494,Transazioni!$G$2:$G$494,A3,Transazioni!$C$2:$C$494,"Entrata") -> 4838.51 | D3: =SUMIFS(Transazioni!$D$2:$D$494,Transazioni!$G$2:$G$494,A3,Transazioni!$C$2:$C$494,"Uscita") -> 2189.95 | E3: =C3-D3 -> 2648.56 | F3: =IFERROR(E3/C3,0) -> 0.54739166 | G3: =G2+E3 -> 5096.36 | I3: RigaMese | J3: =MATCH(J2,$B$2:$B$15,0) -> 14
A4: 202509 | B4: =CHOOSE(MOD(A4,100),"Gen","Feb","Mar","Apr","Mag","Giu","Lug","Ago","Set","Ott","Nov","Dic")&" "&INT(A4/100) -> Set 2025 | C4: =SUMIFS(Transazioni!$D$2:$D$494,Transazioni!$G$2:$G$494,A4,Transazioni!$C$2:$C$494,"Entrata") -> 4821.81 | D4: =SUMIFS(Transazioni!$D$2:$D$494,Transazioni!$G$2:$G$494,A4,Transazioni!$C$2:$C$494,"Uscita") -> 2120.98 | E4: =C4-D4 -> 2700.83 | F4: =IFERROR(E4/C4,0) -> 0.56012784 | G4: =G3+E4 -> 7797.19 | I4: AnnoMeseSelezionato | J4: =INDEX($A$2:$A$15,J3) -> 202608
A5: 202510 | B5: =CHOOSE(MOD(A5,100),"Gen","Feb","Mar","Apr","Mag","Giu","Lug","Ago","Set","Ott","Nov","Dic")&" "&INT(A5/100) -> Ott 2025 | C5: =SUMIFS(Transazioni!$D$2:$D$494,Transazioni!$G$2:$G$494,A5,Transazioni!$C$2:$C$494,"Entrata") -> 4554.33 | D5: =SUMIFS(Transazioni!$D$2:$D$494,Transazioni!$G$2:$G$494,A5,Transazioni!$C$2:$C$494,"Uscita") -> 2164.37 | E5: =C5-D5 -> 2389.96 | F5: =IFERROR(E5/C5,0) -> 0.52476654 | G5: =G4+E5 -> 10187.15 | I5: EntrateMese | J5: =INDEX($C$2:$C$15,J3) -> 4401.16
A6: 202511 | B6: =CHOOSE(MOD(A6,100),"Gen","Feb","Mar","Apr","Mag","Giu","Lug","Ago","Set","Ott","Nov","Dic")&" "&INT(A6/100) -> Nov 2025 | C6: =SUMIFS(Transazioni!$D$2:$D$494,Transazioni!$G$2:$G$494,A6,Transazioni!$C$2:$C$494,"Entrata") -> 4494.97 | D6: =SUMIFS(Transazioni!$D$2:$D$494,Transazioni!$G$2:$G$494,A6,Transazioni!$C$2:$C$494,"Uscita") -> 2369.71 | E6: =C6-D6 -> 2125.26 | F6: =IFERROR(E6/C6,0) -> 0.47280849 | G6: =G5+E6 -> 12312.41 | I6: UsciteMese | J6: =INDEX($D$2:$D$15,J3) -> 2208.82
A7: 202512 | B7: =CHOOSE(MOD(A7,100),"Gen","Feb","Mar","Apr","Mag","Giu","Lug","Ago","Set","Ott","Nov","Dic")&" "&INT(A7/100) -> Dic 2025 | C7: =SUMIFS(Transazioni!$D$2:$D$494,Transazioni!$G$2:$G$494,A7,Transazioni!$C$2:$C$494,"Entrata") -> 4716.74 | D7: =SUMIFS(Transazioni!$D$2:$D$494,Transazioni!$G$2:$G$494,A7,Transazioni!$C$2:$C$494,"Uscita") -> 2249.04 | E7: =C7-D7 -> 2467.7 | F7: =IFERROR(E7/C7,0) -> 0.52317914 | G7: =G6+E7 -> 14780.11 | I7: RisparmioMese | J7: =INDEX($E$2:$E$15,J3) -> 2192.34
A8: 202601 | B8: =CHOOSE(MOD(A8,100),"Gen","Feb","Mar","Apr","Mag","Giu","Lug","Ago","Set","Ott","Nov","Dic")&" "&INT(A8/100) -> Gen 2026 | C8: =SUMIFS(Transazioni!$D$2:$D$494,Transazioni!$G$2:$G$494,A8,Transazioni!$C$2:$C$494,"Entrata") -> 4350.03 | D8: =SUMIFS(Transazioni!$D$2:$D$494,Transazioni!$G$2:$G$494,A8,Transazioni!$C$2:$C$494,"Uscita") -> 2082.8 | E8: =C8-D8 -> 2267.23 | F8: =IFERROR(E8/C8,0) -> 0.5211987 | G8: =G7+E8 -> 17047.34 | I8: TassoRisparmioMese | J8: =INDEX($F$2:$F$15,J3) -> 0.49812777
A9: 202602 | B9: =CHOOSE(MOD(A9,100),"Gen","Feb","Mar","Apr","Mag","Giu","Lug","Ago","Set","Ott","Nov","Dic")&" "&INT(A9/100) -> Feb 2026 | C9: =SUMIFS(Transazioni!$D$2:$D$494,Transazioni!$G$2:$G$494,A9,Transazioni!$C$2:$C$494,"Entrata") -> 4335.84 | D9: =SUMIFS(Transazioni!$D$2:$D$494,Transazioni!$G$2:$G$494,A9,Transazioni!$C$2:$C$494,"Uscita") -> 2274.03 | E9: =C9-D9 -> 2061.81 | F9: =IFERROR(E9/C9,0) -> 0.47552723 | G9: =G8+E9 -> 19109.15 | I9: DeltaRisparmioVsMesePrec | J9: =IF(J3>1,J7-INDEX($E$2:$E$15,J3-1),"") -> -248.35
A10: 202603 | B10: =CHOOSE(MOD(A10,100),"Gen","Feb","Mar","Apr","Mag","Giu","Lug","Ago","Set","Ott","Nov","Dic")&" "&INT(A10/100) -> Mar 2026 | C10: =SUMIFS(Transazioni!$D$2:$D$494,Transazioni!$G$2:$G$494,A10,Transazioni!$C$2:$C$494,"Entrata") -> 5037.22 | D10: =SUMIFS(Transazioni!$D$2:$D$494,Transazioni!$G$2:$G$494,A10,Transazioni!$C$2:$C$494,"Uscita") -> 2046.42 | E10: =C10-D10 -> 2990.8 | F10: =IFERROR(E10/C10,0) -> 0.5937402 | G10: =G9+E10 -> 22099.95 | I10: NumTransazioniMese | J10: =COUNTIFS(Transazioni!$G$2:$G$494,J4) -> 31
A11: 202604 | B11: =CHOOSE(MOD(A11,100),"Gen","Feb","Mar","Apr","Mag","Giu","Lug","Ago","Set","Ott","Nov","Dic")&" "&INT(A11/100) -> Apr 2026 | C11: =SUMIFS(Transazioni!$D$2:$D$494,Transazioni!$G$2:$G$494,A11,Transazioni!$C$2:$C$494,"Entrata") -> 4371.98 | D11: =SUMIFS(Transazioni!$D$2:$D$494,Transazioni!$G$2:$G$494,A11,Transazioni!$C$2:$C$494,"Uscita") -> 1972.74 | E11: =C11-D11 -> 2399.24 | F11: =IFERROR(E11/C11,0) -> 0.54877653 | G11: =G10+E11 -> 24499.19 | I11: SaldoTotaleAttuale | J11: =SUMIFS(Transazioni!$D$2:$D$494,Transazioni!$C$2:$C$494,"Entrata")-SUMIFS(Transazioni!$D$2:$D$494,Transazioni!$C$2:$C$494,"Uscita") -> 33947.02
A12: 202605 | B12: =CHOOSE(MOD(A12,100),"Gen","Feb","Mar","Apr","Mag","Giu","Lug","Ago","Set","Ott","Nov","Dic")&" "&INT(A12/100) -> Mag 2026 | C12: =SUMIFS(Transazioni!$D$2:$D$494,Transazioni!$G$2:$G$494,A12,Transazioni!$C$2:$C$494,"Entrata") -> 4566.81 | D12: =SUMIFS(Transazioni!$D$2:$D$494,Transazioni!$G$2:$G$494,A12,Transazioni!$C$2:$C$494,"Uscita") -> 2319.41 | E12: =C12-D12 -> 2247.4 | F12: =IFERROR(E12/C12,0) -> 0.49211594 | G12: =G11+E12 -> 26746.59 | I12: NumMesiStorico | J12: =14 -> 14
A13: 202606 | B13: =CHOOSE(MOD(A13,100),"Gen","Feb","Mar","Apr","Mag","Giu","Lug","Ago","Set","Ott","Nov","Dic")&" "&INT(A13/100) -> Giu 2026 | C13: =SUMIFS(Transazioni!$D$2:$D$494,Transazioni!$G$2:$G$494,A13,Transazioni!$C$2:$C$494,"Entrata") -> 4701.48 | D13: =SUMIFS(Transazioni!$D$2:$D$494,Transazioni!$G$2:$G$494,A13,Transazioni!$C$2:$C$494,"Uscita") -> 2134.08 | E13: =C13-D13 -> 2567.4 | F13: =IFERROR(E13/C13,0) -> 0.54608336 | G13: =G12+E13 -> 29313.99
A14: 202607 | B14: =CHOOSE(MOD(A14,100),"Gen","Feb","Mar","Apr","Mag","Giu","Lug","Ago","Set","Ott","Nov","Dic")&" "&INT(A14/100) -> Lug 2026 | C14: =SUMIFS(Transazioni!$D$2:$D$494,Transazioni!$G$2:$G$494,A14,Transazioni!$C$2:$C$494,"Entrata") -> 4454.01 | D14: =SUMIFS(Transazioni!$D$2:$D$494,Transazioni!$G$2:$G$494,A14,Transazioni!$C$2:$C$494,"Uscita") -> 2013.32 | E14: =C14-D14 -> 2440.69 | F14: =IFERROR(E14/C14,0) -> 0.54797587 | G14: =G13+E14 -> 31754.68
A15: 202608 | B15: =CHOOSE(MOD(A15,100),"Gen","Feb","Mar","Apr","Mag","Giu","Lug","Ago","Set","Ott","Nov","Dic")&" "&INT(A15/100) -> Ago 2026 | C15: =SUMIFS(Transazioni!$D$2:$D$494,Transazioni!$G$2:$G$494,A15,Transazioni!$C$2:$C$494,"Entrata") -> 4401.16 | D15: =SUMIFS(Transazioni!$D$2:$D$494,Transazioni!$G$2:$G$494,A15,Transazioni!$C$2:$C$494,"Uscita") -> 2208.82 | E15: =C15-D15 -> 2192.34 | F15: =IFERROR(E15/C15,0) -> 0.49812777 | G15: =G14+E15 -> 33947.02
A20: Categoria | B20: Speso | C20: Budget | D20: Percentuale
A21: =Budget!A2 -> Alimentari | B21: =SUMIFS(Transazioni!$D$2:$D$494,Transazioni!$B$2:$B$494,A21,Transazioni!$C$2:$C$494,"Uscita",Transazioni!$G$2:$G$494,$J$4) -> 582.83 | C21: =Budget!B2 -> 550 | D21: =IFERROR(B21/C21,0) -> 1.0596909
A22: =Budget!A3 -> Casa e Bollette | B22: =SUMIFS(Transazioni!$D$2:$D$494,Transazioni!$B$2:$B$494,A22,Transazioni!$C$2:$C$494,"Uscita",Transazioni!$G$2:$G$494,$J$4) -> 879.91 | C22: =Budget!B3 -> 900 | D22: =IFERROR(B22/C22,0) -> 0.97767778
A23: =Budget!A4 -> Trasporti | B23: =SUMIFS(Transazioni!$D$2:$D$494,Transazioni!$B$2:$B$494,A23,Transazioni!$C$2:$C$494,"Uscita",Transazioni!$G$2:$G$494,$J$4) -> 140.55 | C23: =Budget!B4 -> 140 | D23: =IFERROR(B23/C23,0) -> 1.0039286
A24: =Budget!A5 -> Ristoranti e Bar | B24: =SUMIFS(Transazioni!$D$2:$D$494,Transazioni!$B$2:$B$494,A24,Transazioni!$C$2:$C$494,"Uscita",Transazioni!$G$2:$G$494,$J$4) -> 130.41 | C24: =Budget!B5 -> 160 | D24: =IFERROR(B24/C24,0) -> 0.8150625
A25: =Budget!A6 -> Svago | B25: =SUMIFS(Transazioni!$D$2:$D$494,Transazioni!$B$2:$B$494,A25,Transazioni!$C$2:$C$494,"Uscita",Transazioni!$G$2:$G$494,$J$4) -> 77.79 | C25: =Budget!B6 -> 100 | D25: =IFERROR(B25/C25,0) -> 0.7779
A26: =Budget!A7 -> Salute | B26: =SUMIFS(Transazioni!$D$2:$D$494,Transazioni!$B$2:$B$494,A26,Transazioni!$C$2:$C$494,"Uscita",Transazioni!$G$2:$G$494,$J$4) -> 136.69 | C26: =Budget!B7 -> 90 | D26: =IFERROR(B26/C26,0) -> 1.5187778
A27: =Budget!A8 -> Istruzione | B27: =SUMIFS(Transazioni!$D$2:$D$494,Transazioni!$B$2:$B$494,A27,Transazioni!$C$2:$C$494,"Uscita",Transazioni!$G$2:$G$494,$J$4) -> 83.75 | C27: =Budget!B8 -> 60 | D27: =IFERROR(B27/C27,0) -> 1.3958333
A28: =Budget!A9 -> Abbigliamento | B28: =SUMIFS(Transazioni!$D$2:$D$494,Transazioni!$B$2:$B$494,A28,Transazioni!$C$2:$C$494,"Uscita",Transazioni!$G$2:$G$494,$J$4) -> 41.42 | C28: =Budget!B9 -> 90 | D28: =IFERROR(B28/C28,0) -> 0.46022222
A29: =Budget!A10 -> Assicurazioni | B29: =SUMIFS(Transazioni!$D$2:$D$494,Transazioni!$B$2:$B$494,A29,Transazioni!$C$2:$C$494,"Uscita",Transazioni!$G$2:$G$494,$J$4) -> 98.37 | C29: =Budget!B10 -> 100 | D29: =IFERROR(B29/C29,0) -> 0.9837
A30: =Budget!A11 -> Altre Spese | B30: =SUMIFS(Transazioni!$D$2:$D$494,Transazioni!$B$2:$B$494,A30,Transazioni!$C$2:$C$494,"Uscita",Transazioni!$G$2:$G$494,$J$4) -> 37.1 | C30: =Budget!B11 -> 90 | D30: =IFERROR(B30/C30,0) -> 0.41222222
I32: CategoriaMaxSpesa | J32: =INDEX($A$21:$A$30,MATCH(MAX($B$21:$B$30),$B$21:$B$30,0)) -> Casa e Bollette
I33: MaxSpesaValore | J33: =MAX($B$21:$B$30) -> 879.91
I34: CategoriaMaxPercentuale | J34: =INDEX($A$21:$A$30,MATCH(MAX($D$21:$D$30),$D$21:$D$30,0)) -> Salute
I35: MaxPercentuale | J35: =MAX($D$21:$D$30) -> 1.5187778
I36: NumCategorieSforate | J36: =COUNTIF($D$21:$D$30,">1") -> 4
I37: ImportoSforamentoMax | J37: =INDEX($B$21:$B$30,MATCH(MAX($D$21:$D$30),$D$21:$D$30,0))-INDEX($C$21:$C$30,MATCH(MAX($D$21:$D$30),$D$21:$D$30,0)) -> 46.69
A39: Pos | B39: Data | C39: Categoria | D39: Tipo | E39: Valore | F39: ValoreSegnato
A40: 1 | B40: =IFERROR(INDEX(Transazioni!$A$2:$A$494,MATCH($A40,Transazioni!$J$2:$J$494,0)),"") -> 46261.534 | C40: =IFERROR(INDEX(Transazioni!$B$2:$B$494,MATCH($A40,Transazioni!$J$2:$J$494,0)),"") -> Salute | D40: =IFERROR(INDEX(Transazioni!$C$2:$C$494,MATCH($A40,Transazioni!$J$2:$J$494,0)),"") -> Uscita | E40: =IFERROR(INDEX(Transazioni!$D$2:$D$494,MATCH($A40,Transazioni!$J$2:$J$494,0)),"") -> 53.54 | F40: =IF(D40="","",IF(D40="Entrata",E40,-E40)) -> -53.54
A41: 2 | B41: =IFERROR(INDEX(Transazioni!$A$2:$A$494,MATCH($A41,Transazioni!$J$2:$J$494,0)),"") -> 46261.44 | C41: =IFERROR(INDEX(Transazioni!$B$2:$B$494,MATCH($A41,Transazioni!$J$2:$J$494,0)),"") -> Istruzione | D41: =IFERROR(INDEX(Transazioni!$C$2:$C$494,MATCH($A41,Transazioni!$J$2:$J$494,0)),"") -> Uscita | E41: =IFERROR(INDEX(Transazioni!$D$2:$D$494,MATCH($A41,Transazioni!$J$2:$J$494,0)),"") -> 83.75 | F41: =IF(D41="","",IF(D41="Entrata",E41,-E41)) -> -83.75
A42: 3 | B42: =IFERROR(INDEX(Transazioni!$A$2:$A$494,MATCH($A42,Transazioni!$J$2:$J$494,0)),"") -> 46261.378 | C42: =IFERROR(INDEX(Transazioni!$B$2:$B$494,MATCH($A42,Transazioni!$J$2:$J$494,0)),"") -> Stipendio Partner | D42: =IFERROR(INDEX(Transazioni!$C$2:$C$494,MATCH($A42,Transazioni!$J$2:$J$494,0)),"") -> Entrata | E42: =IFERROR(INDEX(Transazioni!$D$2:$D$494,MATCH($A42,Transazioni!$J$2:$J$494,0)),"") -> 1999.98 | F42: =IF(D42="","",IF(D42="Entrata",E42,-E42)) -> 1999.98
A43: 4 | B43: =IFERROR(INDEX(Transazioni!$A$2:$A$494,MATCH($A43,Transazioni!$J$2:$J$494,0)),"") -> 46261.375 | C43: =IFERROR(INDEX(Transazioni!$B$2:$B$494,MATCH($A43,Transazioni!$J$2:$J$494,0)),"") -> Stipendio | D43: =IFERROR(INDEX(Transazioni!$C$2:$C$494,MATCH($A43,Transazioni!$J$2:$J$494,0)),"") -> Entrata | E43: =IFERROR(INDEX(Transazioni!$D$2:$D$494,MATCH($A43,Transazioni!$J$2:$J$494,0)),"") -> 2352.62 | F43: =IF(D43="","",IF(D43="Entrata",E43,-E43)) -> 2352.62
A44: 5 | B44: =IFERROR(INDEX(Transazioni!$A$2:$A$494,MATCH($A44,Transazioni!$J$2:$J$494,0)),"") -> 46260.917 | C44: =IFERROR(INDEX(Transazioni!$B$2:$B$494,MATCH($A44,Transazioni!$J$2:$J$494,0)),"") -> Ristoranti e Bar | D44: =IFERROR(INDEX(Transazioni!$C$2:$C$494,MATCH($A44,Transazioni!$J$2:$J$494,0)),"") -> Uscita | E44: =IFERROR(INDEX(Transazioni!$D$2:$D$494,MATCH($A44,Transazioni!$J$2:$J$494,0)),"") -> 57.89 | F44: =IF(D44="","",IF(D44="Entrata",E44,-E44)) -> -57.89
A45: 6 | B45: =IFERROR(INDEX(Transazioni!$A$2:$A$494,MATCH($A45,Transazioni!$J$2:$J$494,0)),"") -> 46260.738 | C45: =IFERROR(INDEX(Transazioni!$B$2:$B$494,MATCH($A45,Transazioni!$J$2:$J$494,0)),"") -> Trasporti | D45: =IFERROR(INDEX(Transazioni!$C$2:$C$494,MATCH($A45,Transazioni!$J$2:$J$494,0)),"") -> Uscita | E45: =IFERROR(INDEX(Transazioni!$D$2:$D$494,MATCH($A45,Transazioni!$J$2:$J$494,0)),"") -> 31.63 | F45: =IF(D45="","",IF(D45="Entrata",E45,-E45)) -> -31.63
A46: 7 | B46: =IFERROR(INDEX(Transazioni!$A$2:$A$494,MATCH($A46,Transazioni!$J$2:$J$494,0)),"") -> 46257.925 | C46: =IFERROR(INDEX(Transazioni!$B$2:$B$494,MATCH($A46,Transazioni!$J$2:$J$494,0)),"") -> Trasporti | D46: =IFERROR(INDEX(Transazioni!$C$2:$C$494,MATCH($A46,Transazioni!$J$2:$J$494,0)),"") -> Uscita | E46: =IFERROR(INDEX(Transazioni!$D$2:$D$494,MATCH($A46,Transazioni!$J$2:$J$494,0)),"") -> 30.16 | F46: =IF(D46="","",IF(D46="Entrata",E46,-E46)) -> -30.16
...

Sheet Istruzioni
B1: Istruzioni per l'uso — Dashboard Finanze Familiari
B3: 1. Come importare i tuoi dati dal CSV
B4: Il file CSV deve avere queste colonne, nell'ordine: Data e Ora (gg/mm/aaaa hh:mm) · Categoria · Valore (numero positivo) · Tipo (Entrata oppure Uscita).
B6: • Apri il foglio "Transazioni" e cancella le righe di esempio dalla riga 2 in poi (colonne A-D), mantenendo l'intestazione in riga 1.
B7: • Importa il CSV con Dati > Da testo/CSV, oppure incolla i valori direttamente a partire dalla cella A2 nelle colonne A-D.
B8: • Le colonne E-J (Anno, Mese, AnnoMese, MeseEtichetta, Rank, RankMese) sono calcolate automaticamente: seleziona l'ultima riga con formule e trascinala verso il basso per coprire tutte le nuove righe importate.
B9: • Aggiorna anche gli intervalli con riferimento fisso (es. $A$2:$A$494) nei fogli Transazioni, Supporto e Dashboard se il numero di righe cambia in modo consistente.
B11: 2. Come personalizzare il budget
B12: • Nel foglio "Budget" modifica gli importi in colonna B (celle evidenziate in giallo) per ogni categoria di spesa.
B13: • In fondo allo stesso foglio puoi impostare il tuo nome (usato nel saluto della Dashboard) e l'obiettivo di tasso di risparmio mensile.
B15: 3. Come usare la Dashboard
B16: • Usa il menu a tendina "Mese" in alto a destra per cambiare il mese analizzato: le card, i grafici e le liste si aggiornano automaticamente.
... B28: Cella modificabile (sfondo giallo, testo blu) — solo nel foglio Budget
